[2024-04-30 16:11:41,936] {taskinstance.py:877} INFO - Dependencies all met for <TaskInstance: json_file.step3_Decidewhichtask 2024-04-30T16:11:03.994995+00:00 [queued]>
[2024-04-30 16:11:42,019] {taskinstance.py:877} INFO - Dependencies all met for <TaskInstance: json_file.step3_Decidewhichtask 2024-04-30T16:11:03.994995+00:00 [queued]>
[2024-04-30 16:11:42,021] {taskinstance.py:1068} INFO - 
--------------------------------------------------------------------------------
[2024-04-30 16:11:42,026] {taskinstance.py:1069} INFO - Starting attempt 1 of 1
[2024-04-30 16:11:42,028] {taskinstance.py:1070} INFO - 
--------------------------------------------------------------------------------
[2024-04-30 16:11:42,079] {taskinstance.py:1089} INFO - Executing <Task(BranchPythonOperator): step3_Decidewhichtask> on 2024-04-30T16:11:03.994995+00:00
[2024-04-30 16:11:42,086] {standard_task_runner.py:52} INFO - Started process 110 to run task
[2024-04-30 16:11:42,285] {standard_task_runner.py:76} INFO - Running: ['airflow', 'tasks', 'run', 'json_file', 'step3_Decidewhichtask', '2024-04-30T16:11:03.994995+00:00', '--job-id', '14107', '--pool', 'default_pool', '--raw', '--subdir', 'DAGS_FOLDER/json_file.py', '--cfg-path', '/tmp/tmpaa5ncep1', '--error-file', '/tmp/tmpl0o9c5zb']
[2024-04-30 16:11:42,288] {standard_task_runner.py:77} INFO - Job 14107: Subtask step3_Decidewhichtask
[2024-04-30 16:11:42,895] {logging_mixin.py:104} INFO - Running <TaskInstance: json_file.step3_Decidewhichtask 2024-04-30T16:11:03.994995+00:00 [running]> on host c6f0c13ba6da
[2024-04-30 16:11:43,371] {taskinstance.py:1283} INFO - Exporting the following env vars:
AIRFLOW_CTX_DAG_OWNER=airflow
AIRFLOW_CTX_DAG_ID=json_file
AIRFLOW_CTX_TASK_ID=step3_Decidewhichtask
AIRFLOW_CTX_EXECUTION_DATE=2024-04-30T16:11:03.994995+00:00
AIRFLOW_CTX_DAG_RUN_ID=manual__2024-04-30T16:11:03.994995+00:00
[2024-04-30 16:11:43,410] {taskinstance.py:1482} ERROR - Task failed with exception
Traceback (most recent call last):
  File "/home/airflow/.local/lib/python3.6/site-packages/airflow/models/taskinstance.py", line 1138, in _run_raw_task
    self._prepare_and_execute_task_with_callbacks(context, task)
  File "/home/airflow/.local/lib/python3.6/site-packages/airflow/models/taskinstance.py", line 1311, in _prepare_and_execute_task_with_callbacks
    result = self._execute_task(context, task_copy)
  File "/home/airflow/.local/lib/python3.6/site-packages/airflow/models/taskinstance.py", line 1341, in _execute_task
    result = task_copy.execute(context=context)
  File "/home/airflow/.local/lib/python3.6/site-packages/airflow/operators/python.py", line 324, in execute
    branch = super().execute(context)
  File "/home/airflow/.local/lib/python3.6/site-packages/airflow/operators/python.py", line 117, in execute
    return_value = self.execute_callable()
  File "/home/airflow/.local/lib/python3.6/site-packages/airflow/operators/python.py", line 128, in execute_callable
    return self.python_callable(*self.op_args, **self.op_kwargs)
  File "/opt/airflow/dags/json_file.py", line 35, in decideWhichTask
    stepint = int(stepint[1])
UnboundLocalError: local variable 'stepint' referenced before assignment
[2024-04-30 16:11:43,446] {taskinstance.py:1532} INFO - Marking task as FAILED. dag_id=json_file, task_id=step3_Decidewhichtask, execution_date=20240430T161103, start_date=20240430T161141, end_date=20240430T161143
[2024-04-30 16:11:43,550] {local_task_job.py:146} INFO - Task exited with return code 1
